Workbook

Sheet physics_datset_MDSR_top1_shared
A1: ID | B1: TopRank | C1: ModelName | D1: OriginalFormula | E1: GenerationFormula | F1: Target | G1: IndependentVars | H1: ParameterRange | I1: FixedConstantValues | J1: simpFormula | K1: para_eq | L1: orgpara_list | M1: para_list | N1: shared_fit_mse_0_7 | O1: shared_fit_mse_hmean_0_7 | P1: shared_fit_r2_0_7 | Q1: complexity | R1: loss | S1: score | T1: dataset | U1: structure_similarity_score | V1: structure_similarity_level | W1: WASS_0_MSE | X1: WASS_0_NMSE | Y1: WASS_0_R2 | Z1: WASS_025_MSE | AA1: WASS_025_NMSE | AB1: WASS_025_R2 | AC1: WASS_04_MSE | AD1: WASS_04_NMSE | AE1: WASS_04_R2 | AF1: noise_0_MSE | AG1: noise_0_NMSE | AH1: noise_0_R2 | AI1: noise_001_MSE | AJ1: noise_001_NMSE | AK1: noise_001_R2 | AL1: noise_003_MSE | AM1: noise_003_NMSE | AN1: noise_003_R2 | AO1: noise_005_MSE | AP1: noise_005_NMSE | AQ1: noise_005_R2 | AR1: noise_01_MSE | AS1: noise_01_NMSE | AT1: noise_01_R2
A2: P01 | B2: 1 | C2: I.48.2_1_0 | D2: E_n = m*c**2/sqrt(1-v**2/c**2) | E2: c*sqrt(1 - c**4*m**2/E_n**2) | F2: v | G2: E_n | H2: m=[1, 5] | I2: c=6.5 | J2: 6.5*sqrt(1 - 1785.0625*m**2/E_n**2) | K2: p0 + ((E_n*p6 + p5)*log(E_n*(E_n + p1*cos(E_n*p3 + E_n**p2) + sin(E_n)))**p4*cos(E_n**p4))**p4 | L2: [0.00802938500000000, 4.23417117560027, 2, -0.835334655946539, 1/2, -24.9598257281631, 0.159751010000000] | M2: [p0, p1, p2, p3, p4, p5, p6] | N2: 0.0002512004993265 | O2: 0.0002511759314685 | P2: 0.9968287889319174 | Q2: 35 | R2: 0.00025042036 | S2: 8.153624200210737e-05 | T2: 5 | U2: 15 | V2: =IF(U2>=[1]评分标准!$B$5,[1]评分标准!$A$5,IF(U2>=[1]评分标准!$B$6,[1]评分标准!$A$6,IF(U2>=[1]评分标准!$B$7,[1]评分标准!$A$7,IF(U2>=[1]评分标准!$B$8,[1]评分标准!$A$8,[1]评分标准!$A$9)))) -> 不相似 | W2: 0.010041072944234106 | X2: 0.12467855160696444 | Y2: 0.8753214483930356 | Z2: 0.0007304164827212878 | AA2: 0.00903353169901339 | AB2: 0.9909664683009867 | AC2: 0.0006536395462830462 | AD2: 0.008258901561624362 | AE2: 0.9917410984383757 | AF2: 0.0030038074134082823 | AG2: 0.03694277856634169 | AH2: 0.9630572214336584 | AI2: 0.0004977058161748662 | AJ2: 0.006181974296485409 | AK2: 0.9938180257035146 | AL2: 0.0029154708255110543 | AM2: 0.03544089735282907 | AN2: 0.9645591026471709 | AO2: 0.006445005004691216 | AP2: 0.07513327553392331 | AQ2: 0.9248667244660767 | AR2: 0.02570834553808578 | AS2: 0.2433425532883421 | AT2: 0.7566574467116579
A3: P02 | B3: 1 | C3: III.15.14_1_0 | D3: m = (h/(2*pi))**2/(2*E_n*d**2) | E3: h**2/(8*pi**2*d**2*m) | F3: E_n | G3: d | H3: m=[0.02, 0.08] | I3: h=3; pi=3.14159 | J3: 0.113986524158145/(d**2*m) | K3: d**p0*(p1 + p2*cos(p3*(d + d**p6*p5 + p4)**p6)) | L3: [-2, 1.70213190000000, -0.00303061140000000, 2.63726200000000, -0.954673400000000, -0.00223819930000000, -1] | M3: [p0, p1, p2, p3, p4, p5, p6] | N3: 5.619843056518549e-05 | O3: 3.977343125946511e-05 | P3: 0.9998092582451148 | Q3: 17 | R3: 2.1964514e-05 | S3: 4.577629045840389e-05 | T3: 3 | U3: 98 | V3: =IF(U3>=[1]评分标准!$B$5,[1]评分标准!$A$5,IF(U3>=[1]评分标准!$B$6,[1]评分标准!$A$6,IF(U3>=[1]评分标准!$B$7,[1]评分标准!$A$7,IF(U3>=[1]评分标准!$B$8,[1]评分标准!$A$8,[1]评分标准!$A$9)))) -> 高度相似 | W3: 1.5383867310992542e-23 | X3: 6.223764295441509e-23 | Y3: 1 | Z3: 1.0145762586514235e-23 | AA3: 1.8252520918876935e-21 | AB3: 1 | AC3: 1.2089748043575004e-25 | AD3: 4.371809891433267e-23 | AE3: 1 | AF3: 2.6101770751739093e-23 | AG3: 1.4489554361533055e-22 | AH3: 1 | AI3: 5.5257337793804684e-05 | AJ3: 0.00019455895094175113 | AK3: 0.9998054410490582 | AL3: 0.0005093843932245938 | AM3: 0.00173006841871298 | AN3: 0.9982699315812871 | AO3: 0.0013868251979528654 | AP3: 0.004849552349107817 | AQ3: 0.9951504476508922 | AR3: 0.005614784277499474 | AS3: 0.01952531357598704 | AT3: 0.980474686424013
A4: P03 | B4: 1 | C4: I.24.6_3_1 | D4: E_n = 1/2*m*(omega**2+omega_0**2)*1/2*x**2 | E4: 2*sqrt(E_n/(m*(omega**2 + omega_0**2))) | F4: x | G4: E_n, omega | H4: m=[1, 3]; omega_0=[1, 3] | I4: (none) | J4: 2*sqrt(E_n/(m*(omega**2 + omega_0**2))) | K4: p0*(E_n*(omega + p1 + p2*sin(omega*p4 + p3))**p2)**p5 | L4: [0.670624499999814, 1.55208580000000, -1, 0.165704650000000, 0.749545625441857, 1/2] | M4: [p0, p1, p2, p3, p4, p5] | N4: 0.0005008901049227 | O4: 0.0005006064160459 | P4: 0.998368028768846 | Q4: 15 | R4: 0.0004889251 | S4: 0.001726931593542 | T4: 2 | U4: 65 | V4: =IF(U4>=[1]评分标准!$B$5,[1]评分标准!$A$5,IF(U4>=[1]评分标准!$B$6,[1]评分标准!$A$6,IF(U4>=[1]评分标准!$B$7,[1]评分标准!$A$7,IF(U4>=[1]评分标准!$B$8,[1]评分标准!$A$8,[1]评分标准!$A$9)))) -> 中等相似 | W4: 2.4419121655204455e-07 | X4: 2.814358907882776e-07 | Y4: 0.9999997185641092 | Z4: 1.6395435345577201e-07 | AA4: 2.1292519296386893e-07 | AB4: 0.999999787074807 | AC4: 1.2860919195225894e-07 | AD4: 1.781839280213946e-07 | AE4: 0.9999998218160719 | AF4: 1.6818987781028967e-07 | AG4: 5.535027912916349e-07 | AH4: 0.9999994464972087 | AI4: 0.0004986235277623348 | AJ4: 0.0016395067015996133 | AK4: 0.9983604932984004 | AL4: 0.0044616385594554156 | AM4: 0.014461935887697622 | AN4: 0.9855380641123024 | AO4: 0.012516877840561397 | AP4: 0.039558550730425565 | AQ4: 0.9604414492695744 | AR4: 0.05002307073641078 | AS4: 0.1404107659344005 | AT4: 0.8595892340655995
A5: P04 | B5: 1 | C5: I.32.5_1_1 | D5: Pwr = q**2*a**2/(6*pi*epsilon*c**3) | E5: sqrt(6)*sqrt(pi)*sqrt(Pwr*c**3*epsilon)/q | F5: a | G5: Pwr | H5: q=[1, 5] | I5: c=3; epsilon=3; pi=3.14159 | J5: 15.9520779210735*sqrt(6)*sqrt(Pwr)/q | K5: Pwr**p0*(p1 + p2*sin(Pwr**p4*p3) + p5*sin(Pwr**p10*p9) + p5*sin(Pwr**p4*p8) + p5*sin(Pwr**p7*p6) + p5*sin(Pwr*p4 + Pwr**p7*p12 + p11)) | L5: [1/2, 10.8819370741496, 0.00880169800000000, 353.110020000000, -1, -0.00880169800000000, 1.37490880000000, -2, 343.687680000000, 1379.83227619587, 2, 0.800868630000000, 559.412600000000] | M5: [p0, p1, p2, p3, p4, p5, p6, p7, p8, p9, p10, p11, p12] | N5: 0.0013028959462954 | O5: 0.0013022841023415 | P5: 0.9988493797639136 | Q5: 39 | R5: 0.00127088 | S5: 1.95529980101649e-05 | T5: 4 | U5: 98 | V5: =IF(U5>=[1]评分标准!$B$5,[1]评分标准!$A$5,IF(U5>=[1]评分标准!$B$6,[1]评分标准!$A$6,IF(U5>=[1]评分标准!$B$7,[1]评分标准!$A$7,IF(U5>=[1]评分标准!$B$8,[1]评分标准!$A$8,[1]评分标准!$A$9)))) -> 高度相似 | W5: 1.4266579555377542e-23 | X5: 1.2565360382881995e-23 | Y5: 1 | Z5: 1.32585561797196e-23 | AA5: 1.1666801659015327e-23 | AB5: 1 | AC5: 1.354680319949788e-23 | AD5: 1.1915012959928184e-23 | AE5: 1 | AF5: 1.3344612133438024e-23 | AG5: 1.1748693319132407e-23 | AH5: 1 | AI5: 0.0012951124599852846 | AJ5: 0.001139014344316367 | AK5: 0.9988609856556836 | AL5: 0.011826612178225825 | AM5: 0.010301461980256915 | AN5: 0.9896985380197431 | AO5: 0.03253002533782938 | AP5: 0.02783998418413145 | AQ5: 0.9721600158158685 | AR5: 0.1320333262440972 | AS5: 0.10418742684420908 | AT5: 0.8958125731557909
A6: P05 | B6: 1 | C6: II.27.18_1_0 | D6: E_den = epsilon*Ef**2 | E6: sqrt(E_den/epsilon) | F6: Ef | G6: E_den | H6: epsilon=[1, 5] | I6: (none) | J6: sqrt(E_den/epsilon) | K6: E_den*p0*(E_den + p1*exp(E_den*p2*cos(E_den + p3) + cos(E_den**p5*p4)))**p6 | L6: [0.479536680000000, -0.00264526800000000, 0.0518356400000000, 1.59535770000000, 0.642484700000000, 2, -1/2] | M6: [p0, p1, p2, p3, p4, p5, p6] | N6: 0.001306104771714 | O6: 0.001305825886167 | P6: 0.9988438717274802 | Q6: 26 | R6: 0.001264911 | S6: 0.0005781253125533 | T6: 4 | U6: 98 | V6: =IF(U6>=[1]评分标准!$B$5,[1]评分标准!$A$5,IF(U6>=[1]评分标准!$B$6,[1]评分标准!$A$6,IF(U6>=[1]评分标准!$B$7,[1]评分标准!$A$7,IF(U6>=[1]评分标准!$B$8,[1]评分标准!$A$8,[1]评分标准!$A$9)))) -> 高度相似 | W6: 1.1156235341541278e-23 | X6: 9.828146700250768e-24 | Y6: 1 | Z6: 1.201100568043773e-23 | AA6: 1.0571648660150289e-23 | AB6: 1 | AC6: 1.2337557364088896e-23 | AD6: 1.0855864601417917e-23 | AE6: 1 | AF6: 1.139539148063738e-23 | AG6: 9.976628946918624e-24 | AH6: 1 | AI6: 0.001290781608962625 | AJ6: 0.0011278623527617364 | AK6: 0.9988721376472383 | AL6: 0.01161499069550842 | AM6: 0.010046560373982891 | AN6: 0.9899534396260171 | AO6: 0.0325872873140621 | AP6: 0.02768252265617168 | AQ6: 0.9723174773438283 | AR6: 0.13065932635902572 | AS6: 0.10304658090654775 | AT6: 0.8969534190934523
A7: P07 | B7: 1 | C7: II.15.4_1_0 | D7: E_n = -mom*B*cos(theta) | E7: =-E_n/(mom*COS(theta)) -> #NAME? | F7: B | G7: E_n, theta | H7: mom=[1, 5] | I7: (none) | J7: =-E_n/(mom*COS(theta)) -> #NAME? | K7: E_n*p0*(p1*(E_n + p2)*sin(E_n*p3)*sin(E_n*p5 + p4) + cos(theta))**p6 | L7: [-0.479576680000000, -0.000339354106716986, 0.963279100000000, 0.803715609410931, 18.6009332694999, 15.9759710000000, -1] | M7: [p0, p1, p2, p3, p4, p5, p6] | N7: 0.001014208722529 | O7: 0.0010133637874617 | P7: 0.9992440924204276 | Q7: 23 | R7: 0.0009866684 | S7: 0.0003842498157442 | T7: 6 | U7: 98 | V7: =IF(U7>=[1]评分标准!$B$5,[1]评分标准!$A$5,IF(U7>=[1]评分标准!$B$6,[1]评分标准!$A$6,IF(U7>=[1]评分标准!$B$7,[1]评分标准!$A$7,IF(U7>=[1]评分标准!$B$8,[1]评分标准!$A$8,[1]评分标准!$A$9)))) -> 高度相似 | W7: 1.8184447412652928e-21 | X7: 3.3663353237153156e-22 | Y7: 1 | Z7: 1.8169603553170342e-21 | AA7: 3.3634054942207513e-22 | AB7: 1 | AC7: 1.8246386495401003e-21 | AD7: 3.377056813312008e-22 | AE7: 1 | AF7: 5.5939309161313875e-22 | AG7: 4.1638855803452896e-22 | AH7: 1 | AI7: 0.0010312568681291323 | AJ7: 0.0007670561709094101 | AK7: 0.9992329438290906 | AL7: 0.009270448273130592 | AM7: 0.006853028410228017 | AN7: 0.9931469715897719 | AO7: 0.0257100890542876 | AP7: 0.01877553949928328 | AQ7: 0.9812244605007167 | AR7: 0.10191442344855176 | AS7: 0.07027893720303964 | AT7: 0.9297210627969603
A8: P08 | B8: 1 | C8: III.10.19_1_1 | D8: E_n = mom*sqrt(Bx**2+By**2+Bz**2) | E8: sqrt(-By**2 - Bz**2 + E_n**2/mom**2) | F8: Bx | G8: E_n, By, Bz | H8: mom=[1, 5] | I8: (none) | J8: sqrt(-By**2 - Bz**2 + E_n**2/mom**2) | K8: (E_n*p6*(Bz + p7) + p0*(By*E_n**p0*p1*(By**p4*p3*(Bz + E_n)**p0 + p2) + Bz)**p5)**p8 | L8: [-1, 1.77436449982102, 1.02988100000000, 1.17529349723036, 2, 1.80013970000000, 0.217589040000000, 2.59182520000000, 0.718435170000000] | M8: [p0, p1, p2, p3, p4, p5, p6, p7, p8] | N8: 9.735430456032958 | O8: 0.0327444155758393 | P8: -7.2043015 | Q8: 35 | R8: 0.004437976 | S8: 0.1675911841601198 | T8: 5 | U8: 45 | V8: =IF(U8>=[1]评分标准!$B$5,[1]评分标准!$A$5,IF(U8>=[1]评分标准!$B$6,[1]评分标准!$A$6,IF(U8>=[1]评分标准!$B$7,[1]评分标准!$A$7,IF(U8>=[1]评分标准!$B$8,[1]评分标准!$A$8,[1]评分标准!$A$9)))) -> 较低相似 | W8: 0.020683799467717444 | X8: 0.0057648392256550475 | Y8: 0.9942351607743449 | Z8: 0.3456105428958893 | AA8: 0.09538617246820612 | AB8: 0.9046138275317939 | AC8: 0.020483180852355884 | AD8: 0.005693756461964803 | AE8: 0.9943062435380352 | AF8: 0.2346589703457449 | AG8: 0.19935218073116684 | AH8: 0.8006478192688331 | AI8: 0.35665675382270257 | AJ8: 0.30372039624567776 | AK8: 0.6962796037543222 | AL8: 0.2241058237316939 | AM8: 0.1880929547992934 | AN8: 0.8119070452007067 | AO8: 0.08889895965243191 | AP8: 0.07385308989949703 | AQ8: 0.9261469101005029 | AR8: 0.4277583507899904 | AS8: 0.3268367592662418 | AT8: 0.6731632407337582
A9: P09 | B9: 1 | C9: II.34.2_1_0 | D9: mom = q*v*r/2 | E9: 2*mom/(q*r) | F9: v | G9: r | H9: mom=[2, 8] | I9: q=3 | J9: 2*mom/(3*r) | K9: p0*(p1*(p2 + r + sin(r**p5*atan(r) + (p3 + r)**p4))**p5 + r)**p5 | L9: [2.52454660000000, -0.00120222420000000, 0.102998512206849, 1, 10.8644950000000, -1] | M9: [p0, p1, p2, p3, p4, p5] | N9: 0.0003136613927929 | O9: 0.0002391479842643 | P9: 0.99948442441963 | Q9: 26 | R9: 0.00012453702 | S9: 8.511489105118728e-06 | T9: 2 | U9: 98 | V9: =IF(U9>=[1]评分标准!$B$5,[1]评分标准!$A$5,IF(U9>=[1]评分标准!$B$6,[1]评分标准!$A$6,IF(U9>=[1]评分标准!$B$7,[1]评分标准!$A$7,IF(U9>=[1]评分标准!$B$8,[1]评分标准!$A$8,[1]评分标准!$A$9)))) -> 高度相似 | W9: 1.726892167190355e-23 | X9: 2.960517785019178e-23 | Y9: 1 | Z9: 1.8365958112697065e-23 | AA9: 2.8682440865558543e-23 | AB9: 1 | AC9: 1.9138504149374465e-23 | AD9: 2.8422376710072223e-23 | AE9: 1 | AF9: 9.592495773116382e-24 | AG9: 3.037800807607308e-23 | AH9: 1 | AI9: 0.00016939071639470853 | AJ9: 0.0005231351274090912 | AK9: 0.9994768648725909 | AL9: 0.0015625781753680905 | AM9: 0.0047116574964631425 | AN9: 0.9952883425035368 | AO9: 0.00427290818288179 | AP9: 0.012815766289032906 | AQ9: 0.9871842337109671 | AR9: 0.017016950559110317 | AS9: 0.04955485619599795 | AT9: 0.950445143804002
A10: P10 | B10: 1 | C10: I.32.17_2_0 | D10: Pwr = (1/2*epsilon*c*Ef**2)*(8*pi*r**2/3)*(omega**4/(omega**2-omega_0**2)**2) | E10: sqrt(3)*sqrt(Pwr/(c*epsilon))*(-omega**2 + omega_0**2)/(2*sqrt(pi)*omega**2*r) | F10: Ef | G10: Pwr, omega | H10: r=[1, 2]; omega_0=[3, 5] | I10: c=1.5; epsilon=1.5; pi=3.14159 | J10: 0.188063273941061*sqrt(3)*sqrt(Pwr)*(-omega**2 + omega_0**2)/(omega**2*r) | K10: Pwr**p1*p0*(omega**p4*p3 + p2 + p5*atan(exp(sin(Pwr) + cos(Pwr*p8))*cos(Pwr*p7*atan(Pwr) + p6))) | L10: [44.5027600000000, 1/2, -0.00483919630000000, 0.0652686400000000, -2, -1.87151300000000e-5, 1.01515200000000, 1.79131240000000, 4.37218466831361] | M10: [p0, p1, p2, p3, p4, p5, p6, p7, p8] | N10: 0.0002483554226386 | O10: 0.0002482733310755 | P10: 0.9969138340056976 | Q10: 36 | R10: 0.00024343526 | S10: 0.0004869513702779 | T10: 2 | U10: 98 | V10: =IF(U10>=[1]评分标准!$B$5,[1]评分标准!$A$5,IF(U10>=[1]评分标准!$B$6,[1]评分标准!$A$6,IF(U10>=[1]评分标准!$B$7,[1]评分标准!$A$7,IF(U10>=[1]评分标准!$B$8,[1]评分标准!$A$8,[1]评分标准!$A$9)))) -> 高度相似 | W10: 3.697421295659038e-22 | X10: 1.0712721049091537e-22 | Y10: 1 | Z10: 3.4538276693025762e-22 | AA10: 1.0656461720865917e-22 | AB10: 1 | AC10: 3.340473637025965e-22 | AD10: 1.0633610681757015e-22 | AE10: 1 | AF10: 5.600109297528817e-23 | AG10: 7.007918381539331e-22 | AH10: 1 | AI10: 0.0002518014246739893 | AJ10: 0.0031406081211878185 | AK10: 0.9968593918788122 | AL10: 0.002255157220596416 | AM10: 0.027487175193920077 | AN10: 0.9725128248060799 | AO10: 0.00624682138374231 | AP10: 0.07284566032438558 | AQ10: 0.9271543396756143 | AR10: 0.02502288032082455 | AS10: 0.2385564308048174 | AT10: 0.7614435691951826
A11: P11 | B11: 1 | C11: II.11.27_0_0 | D11: Pol = n*alpha/(1-(n*alpha/3))*epsilon*Ef | E11: 3*Pol/(alpha*(3*Ef*epsilon + Pol)) | F11: n | G11: Pol, Ef | H11: alpha=[0, 1] | I11: epsilon=1.5 | J11: 3*Pol/(alpha*(4.5*Ef + Pol)) | K11: Ef**p0*(p1 + p2*sin(Ef**p4*p3)*sin(Pol*p5*log(Ef)**p0))*(Pol*exp(Ef**p0*Pol*p7) + p6) | L11: [-1, 3.06182070000000, -0.00611929550000000, 1.54469509611054, 2, 0.897273900000000, 0.000157062230000000, -0.211466060000000] | M11: [p0, p1, p2, p3, p4, p5, p6, p7] | N11: 2.374870200723834e-05 | O11: 2.3704069188146977e-05 | P11: 0.9994914200946236 | Q11: 32 | R11: 2.2148151e-05 | S11: 0.0007427703896511 | T11: 1 | U11: 35 | V11: =IF(U11>=[1]评分标准!$B$5,[1]评分标准!$A$5,IF(U11>=[1]评分标准!$B$6,[1]评分标准!$A$6,IF(U11>=[1]评分标准!$B$7,[1]评分标准!$A$7,IF(U11>=[1]评分标准!$B$8,[1]评分标准!$A$8,[1]评分标准!$A$9)))) -> 不相似 | W11: 8.808125090760073e-07 | X11: 9.570396931361375e-06 | Y11: 0.9999904296030686 | Z11: 3.678855837002394e-06 | AA11: 4.275437951785349e-05 | AB11: 0.9999572456204822 | AC11: 6.874800940999642e-06 | AD11: 8.324276705614664e-05 | AE11: 0.9999167572329439 | AF11: 5.56335137211091e-08 | AG11: 1.1940727402463137e-06 | AH11: 0.9999988059272598 | AI11: 2.392457279322667e-05 | AJ11: 0.0005118861866598124 | AK11: 0.9994881138133402 | AL11: 0.0002167770711611481 | AM11: 0.004618890415713015 | AN11: 0.995381109584287 | AO11: 0.000608457746289757 | AP11: 0.012855877109324211 | AQ11: 0.9871441228906758 | AR11: 0.0023990266622150413 | AS11: 0.04870638766749088 | AT11: 0.9512936123325091
A12: P12 | B12: 1 | C12: II.11.3_4_1 | D12: x = q*Ef/(m*(omega_0**2-omega**2)) | E12: sqrt(-Ef*q/(m*x) + omega_0**2) | F12: omega | G12: x, Ef | H12: omega_0=[3, 5] | I12: q=2; m=2 | J12: sqrt(-Ef/x + omega_0**2) | K12: (Ef*p1*x**p2 + p0 + p3*(p4 + p5*log(Ef)**p2)*sin(p6*x + atan(Ef + p2*x)))**p7 | L12: [20.3637171937426, -1.00057284099562, -1, -0.00129712339426763, 1.90351360000000, 0.187617030000000, 281.518319509048, 1/2] | M12: [p0, p1, p2, p3, p4, p5, p6, p7] | N12: 0.0002607625301542 | O12: 0.0002605774688497 | P12: 0.9966549095569848 | Q12: 32 | R12: 0.00025419178 | S12: 3.009493417705696e-05 | T12: 2 | U12: 98 | V12: =IF(U12>=[1]评分标准!$B$5,[1]评分标准!$A$5,IF(U12>=[1]评分标准!$B$6,[1]评分标准!$A$6,IF(U12>=[1]评分标准!$B$7,[1]评分标准!$A$7,IF(U12>=[1]评分标准!$B$8,[1]评分标准!$A$8,[1]评分标准!$A$9)))) -> 高度相似 | W12: 1.1317897520418498e-06 | X12: 1.7647619809698715e-06 | Y12: 0.999998235238019 | Z12: 7.245510643622195e-08 | AA12: 1.3155275359519705e-07 | AB12: 0.9999998684472464 | AC12: 3.3332366815389735e-07 | AD12: 6.188139373339487e-07 | AE12: 0.9999993811860627 | AF12: 0.0034712507801697456 | AG12: 0.04510413421987227 | AH12: 0.9548958657801278 | AI12: 0.004315569419650902 | AJ12: 0.05576661360512837 | AK12: 0.9442333863948716 | AL12: 0.0074455017372379445 | AM12: 0.09415903442538132 | AN12: 0.9058409655746187 | AO12: 0.01128459194883271 | AP12: 0.13459493902151123 | AQ12: 0.8654050609784887 | AR12: 0.05158058102876918 | AS12: 0.49671831744851735 | AT12: 0.5032816825514826
A13: P13 | B13: 1 | C13: I.13.12_3_0 | D13: U = G*m1*m2*(1/r2-1/r1) | E13: G*m1*m2*r1/(G*m1*m2 + U*r1) | F13: r2 | G13: U | H13: r1=[1, 5] | I13: G=3; m1=3; m2=3 | J13: 27*r1/(U*r1 + 27) | K13: p0 + (p1 + p2*exp(p3**U) + exp(p4*p5**U))**p6 | L13: [-0.403101500000000, -10.5800608389033, 10.9780293405399, 0.869006160000000, 1.00616591553195, 0.842736900000000, 1/4] | M13: [p0, p1, p2, p3, p4, p5, p6] | N13: 0.0004925968470325 | O13: 0.0004923019153152 | P13: 0.999478482247775 | Q13: 31 | R13: 0.00048304143 | S13: 0.0002539820139978 | T13: 2 | U13: 25 | V13: =IF(U13>=[1]评分标准!$B$5,[1]评分标准!$A$5,IF(U13>=[1]评分标准!$B$6,[1]评分标准!$A$6,IF(U13>=[1]评分标准!$B$7,[1]评分标准!$A$7,IF(U13>=[1]评分标准!$B$8,[1]评分标准!$A$8,[1]评分标准!$A$9)))) -> 不相似 | W13: 1.182534438195251e-08 | X13: 1.2145616118853518e-08 | Y13: 0.9999999878543839 | Z13: 6.359532229700516e-09 | AA13: 6.5903918096873675e-09 | AB13: 0.9999999934096082 | AC13: 8.037694944284551e-09 | AD13: 8.31581762657829e-09 | AE13: 0.9999999916841824 | AF13: 1.722208147083381e-08 | AG13: 1.7934161306248966e-08 | AH13: 0.9999999820658387 | AI13: 0.0004975361982064875 | AJ13: 0.000521043406604832 | AK13: 0.9994789565933953 | AL13: 0.004573963040506832 | AM13: 0.004771825403770909 | AN13: 0.9952281745962291 | AO13: 0.012521363361578766 | AP13: 0.012935453144122245 | AQ13: 0.9870645468558777 | AR13: 0.04945440457455705 | AS13: 0.04959341414731305 | AT13: 0.9504065858526869
A14: P14 | B14: 1 | C14: I.44.4_4_0 | D14: E_n = n*kb*T*ln(V2/V1) | E14: V1*exp(E_n/(T*kb*n)) | F14: V2 | G14: E_n | H14: V1=[1, 5]; T=[1, 5] | I14: kb=3; n=3 | J14: V1*exp(E_n/(9*T)) | K14: p0*exp(E_n*p1 + p2*(p3 + p4*sin(E_n*p5*(E_n + p8)*(E_n*p7 + p6)))*(p7*sin(E_n*p10 + p9) + atan(E_n))) | L14: [2.44035507192829, 0.0490744100000000, -0.0490744100000000, -0.0102724500000000, -0.0102724410000000, 0.710481800000000, 0.0251840500000000, -1, 3.46719500000000, 0.192651143893600, 0.365080480000000] | M14: [p0, p1, p2, p3, p4, p5, p6, p7, p8, p9, p10] | N14: 0.0007452907326895 | O14: 0.000744453712355 | P14: 0.9994201428544152 | Q14: 33 | R14: 0.00072767364 | S14: 0.0002817197190723 | T14: 1 | U14: 98 | V14: =IF(U14>=[1]评分标准!$B$5,[1]评分标准!$A$5,IF(U14>=[1]评分标准!$B$6,[1]评分标准!$A$6,IF(U14>=[1]评分标准!$B$7,[1]评分标准!$A$7,IF(U14>=[1]评分标准!$B$8,[1]评分标准!$A$8,[1]评分标准!$A$9)))) -> 高度相似 | W14: 1.2149514749257602e-23 | X14: 9.541737401317778e-24 | Y14: 1 | Z14: 1.1592571712605724e-23 | AA14: 9.104665163749892e-24 | AB14: 1 | AC14: 1.1319246087461464e-23 | AD14: 8.890204285366562e-24 | AE14: 1 | AF14: 1.1779489730923548e-23 | AG14: 9.160178125720587e-24 | AH14: 1 | AI14: 0.0007475780044489133 | AJ14: 0.0005804860204866849 | AK14: 0.9994195139795132 | AL14: 0.0065622434363503505 | AM14: 0.005069896136057468 | AN14: 0.9949301038639425 | AO14: 0.018523449015855703 | AP14: 0.014198414525810506 | AQ14: 0.9858015854741895 | AR14: 0.07531572060955079 | AS14: 0.05523826354371379 | AT14: 0.9447617364562861
A15: P15 | B15: 1 | C15: II.34.29b_4_0 | D15: E_n = g_*mom*B*Jz/(h/(2*pi)) | E15: E_n*h/(2*pi*Jz*g_*mom) | F15: B | G15: E_n | H15: g_=[1, 5] | I15: h=3; Jz=3; mom=3; pi=3.14159 | J15: 0.0530516925081461*E_n/g_ | K15: E_n*(p0 + p1*exp(p3*sin(E_n**p6*p5 + p4) + sin(E_n*p9 + p8) + cos(E_n*p7))*cos(E_n*(E_n + p2))) | L15: [0.0128395585000000, 6.08872058211584e-6, 0.0720942840000000, -1, -0.503212200000000, 0.0337904400000000, 2, 0.0675808800000000, -0.976624370000000, 0.570261100000000] | M15: [p0, p1, p2, p3, p4, p5, p6, p7, p8, p9] | N15: 0.0010219528509935 | O15: 0.0010215098216896 | P15: 0.9992323320005324 | Q15: 36 | R15: 0.0010020529 | S15: 0.0005113237859245 | T15: 7 | U15: 98 | V15: =IF(U15>=[1]评分标准!$B$5,[1]评分标准!$A$5,IF(U15>=[1]评分标准!$B$6,[1]评分标准!$A$6,IF(U15>=[1]评分标准!$B$7,[1]评分标准!$A$7,IF(U15>=[1]评分标准!$B$8,[1]评分标准!$A$8,[1]评分标准!$A$9)))) -> 高度相似 | W15: 3.159332887282074e-23 | X15: 2.3660416448352356e-23 | Y15: 1 | Z15: 2.889583653985111e-23 | AA15: 2.1638619240538616e-23 | AB15: 1 | AC15: 2.797354453300262e-23 | AD15: 2.0948932070316064e-23 | AE15: 1 | AF15: 3.29361798262312e-23 | AG15: 2.4699241597739638e-23 | AH15: 1 | AI15: 0.0010155970475050594 | AJ15: 0.0007595385613680874 | AK15: 0.9992404614386319 | AL15: 0.009290435813093797 | AM15: 0.006915174252263998 | AN15: 0.993084825747736 | AO15: 0.025893029174662505 | AP15: 0.019000117382832922 | AQ15: 0.9809998826171671 | AR15: 0.10282532472784017 | AS15: 0.07169900995795844 | AT15: 0.9283009900420415
A16: P16 | B16: 1 | C16: II.35.18_4_1 | D16: n = n_0/(exp(mom*B/(kb*T))+exp(-mom*B/(kb*T))) | E16: T*kb*log((n_0 + sqrt(-4*n**2 + n_0**2))/(2*n))/mom | F16: B | G16: n | H16: T=[1, 3]; n_0=[1, 3] | I16: kb=2; mom=2 | J16: T*log((n_0 + sqrt(-4*n**2 + n_0**2))/(2*n)) | K16: p0 + p1*log(n**p2) + p1*log(n*atan(acos(atan(n**p3)))**p4) + p5*atan(n) | L16: [2.18247763000000, -1, 1/2, 3.01997780000000, -0.698932770000000, -1.15104210000000] | M16: [p0, p1, p2, p3, p4, p5] | N16: 0.0004231602941249 | O16: 0.0004227726332525 | P16: 0.9986497212198552 | Q16: 33 | R16: 0.0004195441 | S16: 1.549300536976747e-07 | T16: 4 | U16: 55 | V16: =IF(U16>=[1]评分标准!$B$5,[1]评分标准!$A$5,IF(U16>=[1]评分标准!$B$6,[1]评分标准!$A$6,IF(U16>=[1]评分标准!$B$7,[1]评分标准!$A$7,IF(U16>=[1]评分标准!$B$8,[1]评分标准!$A$8,[1]评分标准!$A$9)))) -> 较低相似 | W16: 1e+100 | X16: 1e+100 | Y16: -1e+100 | Z16: 1e+100 | AA16: 1e+100 | AB16: -1e+100 | AC16: 1e+100 | AD16: 1e+100 | AE16: -1e+100 | AF16: 3.582225705464831e-08 | AG16: 1.1479880003835909e-07 | AH16: 0.9999998852012 | AI16: 0.0004209476396548619 | AJ16: 0.0013498015589945619 | AK16: 0.9986501984410054 | AL16: 0.0037920063754892145 | AM16: 0.012049647936842729 | AN16: 0.9879503520631573 | AO16: 0.010416181538190489 | AP16: 0.032441374909934095 | AQ16: 0.9675586250900658 | AR16: 0.04176012677063785 | AS16: 0.11792941740249847 | AT16: 0.8820705825975015
A17: P17 | B17: 1 | C17: III.13.18_0_0 | D17: v = 2*E_n*d**2*k/(h/(2*pi)) | E17: h*v/(4*pi*d**2*k) | F17: E_n | G17: v, k | H17: d=[1, 5] | I17: h=3; pi=3.14159 | J17: 0.238732616286657*v/(d**2*k) | K17: k**p0*v*(p1 + p2*(k**p0*(exp(sin(p6*v) + cos(p4 + p5*v)) + sin(p7*v)) + p3)*sin(v**p8)) | L17: [-1, 0.0185116720000000, -4.08134070000000e-5, -0.322729080000000, 0.00877205011278480, 0.473865900000000, 1.24091830000000, 2.35818471294005, 1/2] | M17: [p0, p1, p2, p3, p4, p5, p6, p7, p8] | N17: 0.0010312860845516 | O17: 0.001030612452681 | P17: 0.9992269896440942 | Q17: 34 | R17: 0.0010109483 | S17: 9.84214728982036e-06 | T17: 1 | U17: 98 | V17: =IF(U17>=[1]评分标准!$B$5,[1]评分标准!$A$5,IF(U17>=[1]评分标准!$B$6,[1]评分标准!$A$6,IF(U17>=[1]评分标准!$B$7,[1]评分标准!$A$7,IF(U17>=[1]评分标准!$B$8,[1]评分标准!$A$8,[1]评分标准!$A$9)))) -> 高度相似 | W17: 3.956053873771428e-22 | X17: 2.443277390148593e-23 | Y17: 1 | Z17: 3.6029130369550185e-22 | AA17: 2.2260090759989438e-23 | AB17: 1 | AC17: 3.719004799792193e-22 | AD17: 2.2983753563480657e-23 | AE17: 1 | AF17: 4.128180373570863e-23 | AG17: 3.1188332281004056e-23 | AH17: 1 | AI17: 0.001043306588886813 | AJ17: 0.0007872874500325137 | AK17: 0.9992127125499675 | AL17: 0.00930620704013912 | AM17: 0.006971363978502321 | AN17: 0.9930286360214977 | AO17: 0.02603284558410384 | AP17: 0.019279616014391036 | AQ17: 0.9807203839856089 | AR17: 0.10411648126805537 | AS17: 0.07258851573096808 | AT17: 0.9274114842690319
A18: P18 | B18: 1 | C18: I.27.6_2_0 | D18: foc = 1/(1/d1+n/d2) | E18: d2/foc - d2/d1 | F18: n | G18: foc | H18: d1=[1, 5]; d2=[1, 5] | I18: (none) | J18: d2*(1/foc - 1/d1) | K18: p0 + p1*(foc + p2*cos(foc*p3)*cos(foc*p6)*cos(foc**p5*p4))**p7 | L18: [-0.779622100000000, 2.97719930000000, 0.00189494500000000, 10.4514514923575, 0.326141800000000, -5.18736200000000, 1.32761749746757, -1] | M18: [p0, p1, p2, p3, p4, p5, p6, p7] | N18: 0.0006454235817301 | O18: 0.00064428225511 | P18: 0.9994264096525596 | Q18: 23 | R18: 0.0006220366 | S18: 0.0004627007251268 | T18: 5 | U18: 98 | V18: =IF(U18>=[1]评分标准!$B$5,[1]评分标准!$A$5,IF(U18>=[1]评分标准!$B$6,[1]评分标准!$A$6,IF(U18>=[1]评分标准!$B$7,[1]评分标准!$A$7,IF(U18>=[1]评分标准!$B$8,[1]评分标准!$A$8,[1]评分标准!$A$9)))) -> 高度相似 | W18: 2.9404617793703816e-23 | X18: 2.5854805658910997e-23 | Y18: 1 | Z18: 3.2369243572469725e-23 | AA18: 2.8428458592251804e-23 | AB18: 1 | AC18: 3.398127504964137e-23 | AD18: 2.983632061141441e-23 | AE18: 1 | AF18: 2.5613205593593227e-23 | AG18: 2.2388121517019468e-23 | AH18: 1 | AI18: 0.0006416734367815794 | AJ18: 0.0005633021874239116 | AK18: 0.999436697812576 | AL18: 0.005782094008491729 | AM18: 0.005045042449231761 | AN18: 0.9949549575507682 | AO18: 0.016264629445307065 | AP18: 0.014035521082934698 | AQ18: 0.9859644789170653 | AR18: 0.06467896357559053 | AS18: 0.0538796173717436 | AT18: 0.9461203826282564
A19: P19 | B19: 1 | C19: III.4.33_3_0 | D19: E_n = (h/(2*pi))*omega/(exp((h/(2*pi))*omega/(kb*T))-1) | E19: h*omega/(2*pi*kb*log(1 + h*omega/(2*pi*E_n))) | F19: T | G19: E_n | H19: omega=[1, 5] | I19: h=3; kb=3; pi=3.14159 | J19: 0.159155077524438*omega/log(1 + 0.477465232573315*omega/E_n) | K19: E_n*p1*(E_n**p5*p4*(p6 + cos(E_n) + cos(E_n**p9*p8 + p7))*cos(E_n*p10) + p3) + p0 + p1*cos(E_n*p2) | L19: [0.151541860000000, 0.00193411439319579, 0.808578850000000, 172.491000000000, 0.00126148620000000, 2, 0.843163500000000, 0.00433612146121470, 1.94540050000000, 2.47269710000000, 327.260620000000] | M19: [p0, p1, p2, p3, p4, p5, p6, p7, p8, p9, p10] | N19: 0.0010419657375743 | O19: 0.0010410529091123 | P19: 0.9992236871832264 | Q19: 39 | R19: 0.0010004721 | S19: 0.0004462237233102 | T19: 2 | U19: 20 | V19: =IF(U19>=[1]评分标准!$B$5,[1]评分标准!$A$5,IF(U19>=[1]评分标准!$B$6,[1]评分标准!$A$6,IF(U19>=[1]评分标准!$B$7,[1]评分标准!$A$7,IF(U19>=[1]评分标准!$B$8,[1]评分标准!$A$8,[1]评分标准!$A$9)))) -> 不相似 | W19: 1.5849682175263834e-06 | X19: 1.2006185502034253e-06 | Y19: 0.9999987993814499 | Z19: 2.110745815273102e-06 | AA19: 1.5988943039523833e-06 | AB19: 0.9999984011056962 | AC19: 2.489434230733823e-06 | AD19: 1.8857655929168233e-06 | AE19: 0.9999981142344071 | AF19: 3.6110882098887484e-06 | AG19: 2.725669777424361e-06 | AH19: 0.9999972743302226 | AI19: 0.0010314547574680416 | AJ19: 0.0007759327727858828 | AK19: 0.9992240672272141 | AL19: 0.009298028940886452 | AM19: 0.006944769293347435 | AN19: 0.9930552307066526 | AO19: 0.025989274180086813 | AP19: 0.01920164010715542 | AQ19: 0.9807983598928445 | AR19: 0.10344573013967523 | AS19: 0.07211995728296584 | AT19: 0.9278800427170342
A20: P20 | B20: 1 | C20: III.9.52_1_0 | D20: prob = (p_d*Ef*t/(h/(2*pi)))*sin((omega-omega_0)*t/2)**2/((omega-omega_0)*t/2)**2 | E20: h*prob*t*(omega - omega_0)**2/(4*pi*p_d*(1 - cos(t*(omega - omega_0)))) | F20: Ef | G20: prob, t, omega | H20: p_d=[1, 3]; omega_0=[3, 5] | I20: h=2; pi=3.14159 | J20: 0.159155077524438*prob*t*(omega - omega_0)**2/(p_d*(1 - cos(t*(omega - omega_0)))) | K20: omega**p0*t*(p1*prob + p2*(p0*sin(omega*p3 + p4*t) + p5*prob)*sin(omega + p0*t*(omega**p9*p0 + p8))*sin(p6 + p7*t)) | L20: [-1, 0.371086450000000, -1.35974300000000, 2, -1.81493350000000, 0.470452040000000, -0.939362815075212, 0.733021740000000, 2.27240970000000, 1/2] | M20: [p0, p1, p2, p3, p4, p5, p6, p7, p8, p9] | N20: 0.010821699389399 | O20: 0.0086630512454326 | P20: 0.9673017068053232 | Q20: 39 | R20: 0.009653192 | S20: 0.0156001888262995 | T20: 6 | U20: 45 | V20: =IF(U20>=[1]评分标准!$B$5,[1]评分标准!$A$5,IF(U20>=[1]评分标准!$B$6,[1]评分标准!$A$6,IF(U20>=[1]评分标准!$B$7,[1]评分标准!$A$7,IF(U20>=[1]评分标准!$B$8,[1]评分标准!$A$8,[1]评分标准!$A$9)))) -> 较低相似 | W20: 359198738974902.75 | X20: 0.9982901022196642 | Y20: 0.0017098977803357562 | Z20: 192701300888397.12 | AA20: 0.997572631988273 | AB20: 0.0024273680117270074 | AC20: 3692118176786491.0 | AD20: 0.9974403320400645 | AE20: 0.002559667959935452 | AF20: 0.008797955786362038 | AG20: 0.026532192914034462 | AH20: 0.9734678070859655 | AI20: 0.009220731656205555 | AJ20: 0.027759979097630644 | AK20: 0.9722400209023694 | AL20: 0.012688970638983423 | AM20: 0.03784107257612854 | AN20: 0.9621589274238715 | AO20: 0.019481860493630897 | AP20: 0.057095532962002885 | AQ20: 0.9429044670379971 | AR20: 0.05099749000326577 | AS20: 0.1369609830354066 | AT20: 0.8630390169645933
A21: P21 | B21: 1 | C21: II.21.32_3_0 | D21: Volt = q/(4*pi*epsilon*r*(1-v/c)) | E21: c - c*q/(4*pi*Volt*epsilon*r) | F21: v | G21: Volt, r | H21: q=[1, 5] | I21: c=6.5; epsilon=3; pi=3.14159 | J21: 6.5 - 0.172418000651475*q/(Volt*r) | K21: p0*log(Volt*r*(Volt**p4*p3*(p5 + cos(Volt**p7*p6))*cos(p8*r + p8*atan(r*atan(Volt)**p7)) + p2) + p1) | L21: [2.45698430000000, -1.89966250000000, 29.3253860000000, -1.18938818347597, 2, 0.903872700000000, 3.87739175456358, -1, 139.288680000000] | M21: [p0, p1, p2, p3, p4, p5, p6, p7, p8] | N21: 0.0002408563742944 | O21: 0.0002407447911014 | P21: 0.9970985075799184 | Q21: 37 | R21: 0.00023394293 | S21: 0.0001520768104516 | T21: 0 | U21: 35 | V21: =IF(U21>=[1]评分标准!$B$5,[1]评分标准!$A$5,IF(U21>=[1]评分标准!$B$6,[1]评分标准!$A$6,IF(U21>=[1]评分标准!$B$7,[1]评分标准!$A$7,IF(U21>=[1]评分标准!$B$8,[1]评分标准!$A$8,[1]评分标准!$A$9)))) -> 不相似 | W21: 1e+100 | X21: 1e+100 | Y21: -1e+100 | Z21: 1e+100 | AA21: 1e+100 | AB21: -1e+100 | AC21: 1e+100 | AD21: 1e+100 | AE21: -1e+100 | AF21: 1e+100 | AG21: 1e+100 | AH21: -1e+100 | AI21: 1e+100 | AJ21: 1e+100 | AK21: -1e+100 | AL21: 1e+100 | AM21: 1e+100 | AN21: -1e+100 | AO21: 1e+100 | AP21: 1e+100 | AQ21: -1e+100 | AR21: 1e+100 | AS21: 1e+100 | AT21: -1e+100
A22: P22 | B22: 1 | C22: I.15.3t_0_0 | D22: t1 = (t-u*x/c**2)/sqrt(1-u**2/c**2) | E22: c**2*(t - t1*sqrt((c**2 - u**2)/c**2))/u | F22: x | G22: t, t1 | H22: u=[1, 2] | I22: c=6.5 | J22: 42.25*(t - t1*sqrt(1.0 - 0.0236686390532544*u**2))/u | K22: p0 + p1*t + p2*t1 + (p3*t1 + t)*(p4 + p5*cos(p6*t**p6*(p3*t1 + p7)) + p5*tanh(t)) | L22: [0.00248189800000000, 3, -2.40027300000000, -1, 32.4312320000000, 0.0508511070000000, 2, -0.939307450000000] | M22: [p0, p1, p2, p3, p4, p5, p6, p7] | N22: 0.0010174241798524 | O22: 0.0010168483983898 | P22: 0.9992373251991606 | Q22: 32 | R22: 0.0009820614 | S22: 0.000133689424597 | T22: 5 | U22: 98 | V22: =IF(U22>=[1]评分标准!$B$5,[1]评分标准!$A$5,IF(U22>=[1]评分标准!$B$6,[1]评分标准!$A$6,IF(U22>=[1]评分标准!$B$7,[1]评分标准!$A$7,IF(U22>=[1]评分标准!$B$8,[1]评分标准!$A$8,[1]评分标准!$A$9)))) -> 高度相似 | W22: 1.3735721504743678e-20 | X22: 6.617992160738153e-24 | Y22: 1 | Z22: 9.363329516946247e-21 | AA22: 6.259703673902772e-24 | AB22: 1 | AC22: 7.699199421855574e-21 | AD22: 6.0992189067631746e-24 | AE22: 1 | AF22: 1.6233454861152078e-20 | AG22: 1.2188034350123484e-20 | AH22: 1 | AI22: 0.0010329350775809864 | AJ22: 0.0007768663628574448 | AK22: 0.9992231336371425 | AL22: 0.009306856459797126 | AM22: 0.006954077689503519 | AN22: 0.9930459223104965 | AO22: 0.025776624499909723 | AP22: 0.01907911598962495 | AQ22: 0.9809208840103751 | AR22: 0.10316912908064615 | AS22: 0.07200227324667632 | AT22: 0.9279977267533237
A23: P23 | B23: 1 | C23: II.13.23_1_0 | D23: rho_c = rho_c_0/sqrt(1-v**2/c**2) | E23: c*sqrt(1 - rho_c_0**2/rho_c**2) | F23: v | G23: rho_c | H23: rho_c_0=[1, 5] | I23: c=6.5 | J23: 6.5*sqrt(1 - rho_c_0**2/rho_c**2) | K23: p0 + (p1 + rho_c)*(p2*cos(rho_c)**p3 + rho_c) | L23: [0.840182500000000, -0.247740570000000, 0.159759360000000, -1] | M23: [p0, p1, p2, p3] | N23: 41.15787569230879 | O23: 0.0019864779768856 | P23: -511.3074 | Q23: 11 | R23: 0.0002484048 | S23: 0.0008076291815648 | T23: 3 | U23: 25 | V23: =IF(U23>=[1]评分标准!$B$5,[1]评分标准!$A$5,IF(U23>=[1]评分标准!$B$6,[1]评分标准!$A$6,IF(U23>=[1]评分标准!$B$7,[1]评分标准!$A$7,IF(U23>=[1]评分标准!$B$8,[1]评分标准!$A$8,[1]评分标准!$A$9)))) -> 不相似 | W23: 1.9995649874235708 | X23: 25.013431063015055 | Y23: -24.013431 | Z23: 3.3555551658006664 | AA23: 42.285913707789874 | AB23: -41.285914 | AC23: 6.035266396307296 | AD23: 76.06555564282579 | AE23: -75.065556 | AF23: 3.646049646210462e-05 | AG23: 0.0004561930462808437 | AH23: 0.9995438069537191 | AI23: 1.370152393931914 | AJ23: 17.05886762576798 | AK23: -16.058868 | AL23: 1.3719609098896521 | AM23: 16.736100423579067 | AN23: -15.7361 | AO23: 0.006358568102239311 | AP23: 0.07345919530059543 | AQ23: 0.9265408046994046 | AR23: 1.395664658389627 | AS23: 13.201478724399974 | AT23: -12.201479
A24: P24 | B24: 1 | C24: I.10.7_1_0 | D24: m = m_0/sqrt(1-v**2/c**2) | E24: c*sqrt(1 - m_0**2/m**2) | F24: v | G24: m | H24: m_0=[1, 5] | I24: c=6.5 | J24: 6.5*sqrt(1 - m_0**2/m**2) | K24: p0 + p4*atan(p5*(p6 + sin(m))*sin(m*p8 + p7)) + ((p1 + p2*cos(m))**sin(m))**p3 | L24: [0.00586067840000000, -9.16174300000000, -48.2665200000000, 1/2, -1, 0.172436220000000, -0.976649760000000, -5995.52665057871, 12148.5780818270] | M24: [p0, p1, p2, p3, p4, p5, p6, p7, p8] | N24: 0.000264851183151 | O24: 0.0002643283809213 | P24: 0.9967109396258036 | Q24: 26 | R24: 0.0002467077 | S24: 1.2160138558251054e-07 | T24: 2 | U24: 20 | V24: =IF(U24>=[1]评分标准!$B$5,[1]评分标准!$A$5,IF(U24>=[1]评分标准!$B$6,[1]评分标准!$A$6,IF(U24>=[1]评分标准!$B$7,[1]评分标准!$A$7,IF(U24>=[1]评分标准!$B$8,[1]评分标准!$A$8,[1]评分标准!$A$9)))) -> 不相似 | W24: 0.020087178829377907 | X24: 0.24986209074668955 | Y24: 0.7501379092533105 | Z24: 0.020123674225313335 | AA24: 0.24997018725071873 | AB24: 0.7500298127492813 | AC24: 0.049046685085063296 | AD24: 0.6127063693386505 | AE24: 0.3872936306613495 | AF24: 0.05477270010886236 | AG24: 0.6792243228157688 | AH24: 0.3207756771842311 | AI24: 0.045383935767069734 | AJ24: 0.5612611991144413 | AK24: 0.4387388008855587 | AL24: 0.029465225947010634 | AM24: 0.3559461457190787 | AN24: 0.6440538542809213 | AO24: 0.038327056035854415 | AP24: 0.4432797816369599 | AQ24: 0.5567202183630402 | AR24: 0.07132708979927366 | AS24: 0.6787932590395697 | AT24: 0.3212067409604302
A25: P25 | B25: 1 | C25: II.15.5_1_0 | D25: E_n = -p_d*Ef*cos(theta) | E25: =-E_n/(p_d*COS(theta)) -> #NAME? | F25: Ef | G25: E_n, theta | H25: p_d=[1, 5] | I25: (none) | J25: =-E_n/(p_d*COS(theta)) -> #NAME? | K25: E_n*p0*(E_n*p2*(p3*sin(E_n*p1) + p3*sin(p4*theta) + cos(E_n + p5))*sin(E_n + p6) + p1)**p3*cos(theta)**p3 | L25: [-0.987002430000000, 4.07745700000000, 0.000584012770000000, -1, 79029.4051029919, 0.737069130000000, 0.229752210000000] | M25: [p0, p1, p2, p3, p4, p5, p6] | N25: 0.0010271036164137 | O25: 0.0010263240532867 | P25: 0.9992328537878366 | Q25: 27 | R25: 0.0010192763 | S25: 9.569600034154122e-05 | T25: 7 | U25: 98 | V25: =IF(U25>=[1]评分标准!$B$5,[1]评分标准!$A$5,IF(U25>=[1]评分标准!$B$6,[1]评分标准!$A$6,IF(U25>=[1]评分标准!$B$7,[1]评分标准!$A$7,IF(U25>=[1]评分标准!$B$8,[1]评分标准!$A$8,[1]评分标准!$A$9)))) -> 高度相似 | W25: 9.683055149386611e-16 | X25: 1.7964304256514975e-16 | Y25: 0.9999999999999998 | Z25: 4.76206344805532e-14 | AA25: 8.74925114581414e-15 | AB25: 0.9999999999999913 | AC25: 2.0325387623840226e-14 | AD25: 3.7315740018488084e-15 | AE25: 0.9999999999999962 | AF25: 2.808543959978584e-14 | AG25: 2.0645756578692242e-14 | AH25: 0.9999999999999793 | AI25: 0.0010391529369718371 | AJ25: 0.0007710415956937594 | AK25: 0.9992289584043063 | AL25: 0.009299512127537934 | AM25: 0.006868381795066157 | AN25: 0.9931316182049339 | AO25: 0.02598518198017451 | AP25: 0.018947750535239866 | AQ25: 0.9810522494647602 | AR25: 0.10410519629707726 | AS25: 0.07179079827884485 | AT25: 0.9282092017211552
A26: P26 | B26: 1 | C26: Newton cooling | D26: T = Ta + (T0-Ta)*exp(-k*t) | E26: =-LOG((_xleta.T-Ta)/(T0-Ta))/k -> #VALUE! | F26: t | G26: T | H26: T0=[340, 380]; Ta=[285, 305]; k=[0.02, 0.08] | I26: (none) | J26: =-LOG((_xleta.T-Ta)/(T0-Ta))/k -> #VALUE! | K26: p0*(T**p1*p3*exp(p1*cos(T*p6))*cos(T*p5 + p4) + T**p1*(T + p2))*(T*p10 + p7 + p8*(T + p9)**p1) | L26: [0.965564400000000, -1, -2.57751920000000, 0.245946600000000, 0.560977600000000, 500.408170000000, 1.74019482873264, -2.90661760000000, 1983.91360000000, -258.756680000000, -0.0487634500000000] | M26: [p0, p1, p2, p3, p4, p5, p6, p7, p8, p9, p10] | N26: 0.0028735077149075 | O26: 0.0028639459139931 | P26: 0.99964925816847 | Q26: 38 | R26: 0.002545595 | S26: 0.0009927914970886 | T26: 5 | U26: 20 | V26: =IF(U26>=[1]评分标准!$B$5,[1]评分标准!$A$5,IF(U26>=[1]评分标准!$B$6,[1]评分标准!$A$6,IF(U26>=[1]评分标准!$B$7,[1]评分标准!$A$7,IF(U26>=[1]评分标准!$B$8,[1]评分标准!$A$8,[1]评分标准!$A$9)))) -> 不相似 | W26: 1.1788897757173914e-10 | X26: 1.444790310814188e-11 | Y26: 0.9999999999855521 | Z26: 1.9928314331024733e-05 | AA26: 3.687948886813872e-06 | AB26: 0.9999963120511132 | AC26: 0.00023840031057033366 | AD26: 6.532448293235165e-05 | AE26: 0.9999346755170677 | AF26: 3.7533944790328365e-09 | AG26: 4.5743339903710054e-10 | AH26: 0.9999999995425666 | AI26: 0.002953485665528185 | AJ26: 0.0003570878070342523 | AK26: 0.9996429121929657 | AL26: 0.02664422922366526 | AM26: 0.003213375860561439 | AN26: 0.9967866241394385 | AO26: 0.0735965776975229 | AP26: 0.008832120237228683 | AQ26: 0.9911678797627713 | AR26: 0.29849052725526737 | AS26: 0.034824198124474626 | AT26: 0.9651758018755254
A27: P27 | B27: 1 | C27: Magnetic field on axis of current loop | D27: B = mu0*I*R**2/(2*(R**2+z**2)**(3/2)) | E27: sqrt((mu0*I*R**2/(2*B))**(2/3) - R**2) | F27: z | G27: B | H27: I=[2, 5]; R=[1, 2] | I27: mu0=1 | J27: sqrt(-R**2 + 2**(1/3)*(I*R**2/B)**(2/3)/2) | K27: p0 + ((p7 + (B**p4*(B + p8)**p9)**p10)*(B*p2 + p1 + p3*(B + p6)*(B**p4)**p5)**p4)**p11 | L27: [-0.140808180000000, 0.343478680000000, 0.0182034700000000, 0.0530470165416941, -1, -1/2, 0.000925313335914012, -0.605581760000000, 0.000925313600000000, 1/2, 1.87770770000000, 0.370349140000000] | M27: [p0, p1, p2, p3, p4, p5, p6, p7, p8, p9, p10, p11] | N27: 0.0001762837638017 | O27: 0.0001733981231716 | P27: 0.9996044037588216 | Q27: 36 | R27: 0.00016046896 | S27: 7.4364538919763795e-06 | T27: 4 | U27: 95 | V27: =IF(U27>=[1]评分标准!$B$5,[1]评分标准!$A$5,IF(U27>=[1]评分标准!$B$6,[1]评分标准!$A$6,IF(U27>=[1]评分标准!$B$7,[1]评分标准!$A$7,IF(U27>=[1]评分标准!$B$8,[1]评分标准!$A$8,[1]评分标准!$A$9)))) -> 高度相似 | W27: 1.0577676062768422e-06 | X27: 2.441031677593206e-06 | Y27: 0.9999975589683224 | Z27: 9.803014251293419e-06 | AA27: 2.1843806841987615e-05 | AB27: 0.999978156193158 | AC27: 1.13964224982224e-06 | AD27: 2.427479063813372e-06 | AE27: 0.9999975725209362 | AF27: 1.7746628697017046e-05 | AG27: 3.921476319937337e-05 | AH27: 0.9999607852368007 | AI27: 0.00021033947963356069 | AJ27: 0.0004501257109164427 | AK27: 0.9995498742890836 | AL27: 0.001749027476527297 | AM27: 0.0037208556070255513 | AN27: 0.9962791443929744 | AO27: 0.004836076077111701 | AP27: 0.0102062400250558 | AQ27: 0.9897937599749442 | AR27: 0.01908564718800133 | AS27: 0.039075619729129644 | AT27: 0.9609243802708703
A28: P28 | B28: 1 | C28: Kepler third law (Newtonian two-body form) | D28: t = 2*pi*d**(3/2)/sqrt(G*(m1+m2)) | E28: (G*M*T**2/(4*pi**2))**(1/3) | F28: a | G28: T | H28: M=[2, 6] | I28: G=2; pi=3.14159 | J28: 0.233097169776895*2**(2/3)*(M*T**2)**(1/3) | K28: p0*(T**p1)**p2 + p3*(p4 + p7*sin(T) + ((p1*atan(p5 + sin(p6 + exp(T))))**sin(T))**T)**p8 | L28: [0.639970676732726, -1, -0.661097170000000, -0.0180228260000000, 1.68157370000000, -1.68158650000000, -2.07694910000000, 0.509085314706105, -0.228279550000000] | M28: [p0, p1, p2, p3, p4, p5, p6, p7, p8] | N28: 0.0004666755010971 | O28: 0.0004660032211849 | P28: 0.9985494555770532 | Q28: 39 | R28: 0.0004507029 | S28: 0.0001544579000021 | T28: 1 | U28: 98 | V28: =IF(U28>=[1]评分标准!$B$5,[1]评分标准!$A$5,IF(U28>=[1]评分标准!$B$6,[1]评分标准!$A$6,IF(U28>=[1]评分标准!$B$7,[1]评分标准!$A$7,IF(U28>=[1]评分标准!$B$8,[1]评分标准!$A$8,[1]评分标准!$A$9)))) -> 高度相似 | W28: 1.1577657738036817e-23 | X28: 3.5613648831955615e-23 | Y28: 1 | Z28: 4.331619754159196e-22 | AA28: 1.3517131422682317e-21 | AB28: 1 | AC28: 7.636456650508092e-23 | AD28: 2.378902762686354e-22 | AE28: 1 | AF28: 1.339253152872033e-23 | AG28: 4.164006057449821e-23 | AH28: 1 | AI28: 0.0004558172930164479 | AJ28: 0.001416405209750571 | AK28: 0.9985835947902495 | AL28: 0.00419612242037269 | AM28: 0.0128930329009296 | AN28: 0.9871069670990704 | AO28: 0.011744454612562247 | AP28: 0.03528651872967621 | AQ28: 0.9647134812703239 | AR28: 0.04630544873948166 | AS28: 0.12563350085953473 | AT28: 0.8743664991404654
A29: P29 | B29: 1 | C29: Uniform-acceleration position | D29: x = x0 + v0*t + 0.5*a*t**2 | E29: (-v0 + sqrt(v0**2 + 2*a*(x-x0)))/a | F29: t | G29: x | H29: x0=[0, 2]; v0=[1, 4]; a=[0.5, 2] | I29: (none) | J29: (-v0 + sqrt(2*a*(x - x0) + v0**2))/a | K29: p0 + x*(p4 + p5*x*(cos(p6*x**p7) + cos(p8*x)) + p5*x)*cos(x)*cos(p9*x) + (p1 + p2*x)**p3 | L29: [-2.31448600000000, 3.38447496497747, 1.56420430000000, 1/2, -1.44155955384000e-5, -9.89385600000000e-6, 0.730333750000000, 2, 3.64751388736200, 0.187837000000000] | M29: [p0, p1, p2, p3, p4, p5, p6, p7, p8, p9] | N29: 0.0010704667668099 | O29: 0.0010683272125338 | P29: 0.9994198600207184 | Q29: 37 | R29: 0.0010352337 | S29: 1.2605690383174888e-05 | T29: 3 | U29: 98 | V29: =IF(U29>=[1]评分标准!$B$5,[1]评分标准!$A$5,IF(U29>=[1]评分标准!$B$6,[1]评分标准!$A$6,IF(U29>=[1]评分标准!$B$7,[1]评分标准!$A$7,IF(U29>=[1]评分标准!$B$8,[1]评分标准!$A$8,[1]评分标准!$A$9)))) -> 高度相似 | W29: 1.931919988951425e-23 | X29: 1.0403966829791273e-23 | Y29: 1 | Z29: 1.753185966235112e-23 | AA29: 9.51915438843879e-24 | AB29: 1 | AC29: 3.306893608007136e-22 | AD29: 1.785442803556639e-22 | AE29: 1 | AF29: 2.1820332665918434e-21 | AG29: 1.1396580830207756e-21 | AH29: 1 | AI29: 0.0010496676777686708 | AJ29: 0.0005600357529839865 | AK29: 0.999439964247016 | AL29: 0.009469318280939042 | AM29: 0.00503110337657619 | AN29: 0.9949688966234238 | AO29: 0.02672849021295889 | AP29: 0.014054129972777486 | AQ29: 0.9859458700272226 | AR29: 0.10567450758045341 | AS29: 0.05317987898087754 | AT29: 0.9468201210191225
A30: P30 | B30: 1 | C30: Linear-drag velocity relaxation | D30: v = v_inf + (v0-v_inf)*exp(-t/tau) | E30: =-tau*LOG((v-v_inf)/(v0-v_inf)) -> #NAME? | F30: t | G30: v | H30: v_inf=[0, 2]; v0=[8, 12]; tau=[1, 4] | I30: (none) | J30: =-tau*LOG((v-v_inf)/(v0-v_inf)) -> #NAME? | K30: (p0 + p1*v**p2*cos(p3*v)*cos(p4 + v))*(p5 + p6*log(p7 + v)) | L30: [2.38260410000000, -0.0105444956098520, -2, 2017.94730000000, -0.623766360000000, 2.34366440000000, -1, -0.623752800000000] | M30: [p0, p1, p2, p3, p4, p5, p6, p7] | N30: 0.0010179318504385 | O30: 0.0009733641078515 | P30: 0.9997714678237072 | Q30: 23 | R30: 0.0008865327 | S30: 0.000214689844633 | T30: 1 | U30: 98 | V30: =IF(U30>=[1]评分标准!$B$5,[1]评分标准!$A$5,IF(U30>=[1]评分标准!$B$6,[1]评分标准!$A$6,IF(U30>=[1]评分标准!$B$7,[1]评分标准!$A$7,IF(U30>=[1]评分标准!$B$8,[1]评分标准!$A$8,[1]评分标准!$A$9)))) -> 高度相似 | W30: 3.2423829268179194e-22 | X30: 6.239589762246581e-23 | Y30: 1 | Z30: 2.4922955935586713e-22 | AA30: 4.533435166373309e-23 | AB30: 1 | AC30: 2.9098182725390114e-22 | AD30: 6.098758424640349e-23 | AE30: 1 | AF30: 1.1020874421527327e-21 | AG30: 3.4421746529592375e-22 | AH30: 1 | AI30: 0.0008684650915102151 | AJ30: 0.000218662527826218 | AK30: 0.9997813374721738 | AL30: 0.007716161227345169 | AM30: 0.0019334902283140425 | AN30: 0.998066509771686 | AO30: 0.021786386780234465 | AP30: 0.005448951209302456 | AQ30: 0.9945510487906976 | AR30: 0.08588580207619348 | AS30: 0.0212596835789745 | AT30: 0.9787403164210254
A31: P31 | B31: 1 | C31: Quadratic-drag terminal fall from rest | D31: v = v_t*tanh(g*t/v_t) | E31: (v_t/g)*atanh(v/v_t) | F31: t | G31: v | H31: v_t=[20, 50] | I31: g=9.81 | J31: 0.101936799184506*v_t*atanh(v/v_t) | K31: (p0 + p1*v**p2*(p3*(p4 + sin(v*(p5 + p6*v**p7)))*sin(v**v) + v))*atanh(p6 + Mod(p8 + p9*v, p2)) | L31: [-2.72023400000000, -2.12774760000000e-6, 2, 4.25497838853927, -1.20771720000000, 0.286532580000000, -1, 1.85164050000000, 1.00000000000000, -0.0374465200000000] | M31: [p0, p1, p2, p3, p4, p5, p6, p7, p8, p9] | N31: 0.0002510117968812 | O31: 0.0002496047338519 | P31: 0.999647593880227 | Q31: 34 | R31: 0.00022075447 | S31: 0.0002754824458175 | T31: 1 | U31: 95 | V31: =IF(U31>=[1]评分标准!$B$5,[1]评分标准!$A$5,IF(U31>=[1]评分标准!$B$6,[1]评分标准!$A$6,IF(U31>=[1]评分标准!$B$7,[1]评分标准!$A$7,IF(U31>=[1]评分标准!$B$8,[1]评分标准!$A$8,[1]评分标准!$A$9)))) -> 高度相似 | W31: 1.4327265202817423e-23 | X31: 2.017142398398915e-23 | Y31: 1 | Z31: 1.4329730388312244e-23 | AA31: 2.01479138255517e-23 | AB31: 1 | AC31: 1.421775611722839e-23 | AD31: 1.998230074595294e-23 | AE31: 1 | AF31: 1.6632457779942088e-23 | AG31: 2.4542820740525562e-23 | AH31: 1 | AI31: 0.00023807048567263677 | AJ31: 0.00034867244870352715 | AK31: 0.9996513275512965 | AL31: 0.00210693229654566 | AM31: 0.003081061222046289 | AN31: 0.9969189387779538 | AO31: 0.005856353307588071 | AP31: 0.008522484058614851 | AQ31: 0.9914775159413851 | AR31: 0.02367343786581636 | AS31: 0.03347320128666616 | AT31: 0.9665267987133338
A32: P32 | B32: 1 | C32: Bernoulli pressure-speed relation | D32: P = P0 - 0.5*rho*v**2 | E32: sqrt(2*(P0-P)/rho) | F32: v | G32: P | H32: P0=[8, 12]; rho=[1, 3] | I32: (none) | J32: sqrt(2)*sqrt((-P + P0)/rho) | K32: (P*p1 + p0 + p2*(P**P*p4*(p5 + cos(P*p6)) + p3)**p4)**p7 | L32: [8.45781774547450, -0.768158919718398, -0.959357929972180, 0.727697495762345, -1, 0.0571483450000000, 1.33286950000000, 1/2] | M32: [p0, p1, p2, p3, p4, p5, p6, p7] | N32: 0.0998070693313355 | O32: 0.0015073300537403 | P32: 0.552913780956898 | Q32: 25 | R32: 0.00019260883 | S32: 0.0006449333191119 | T32: 1 | U32: 98 | V32: =IF(U32>=[1]评分标准!$B$5,[1]评分标准!$A$5,IF(U32>=[1]评分标准!$B$6,[1]评分标准!$A$6,IF(U32>=[1]评分标准!$B$7,[1]评分标准!$A$7,IF(U32>=[1]评分标准!$B$8,[1]评分标准!$A$8,[1]评分标准!$A$9)))) -> 高度相似 | W32: 0.00032375672112586645 | X32: 0.0014267949442243316 | Y32: 0.9985732050557756 | Z32: 1.0257789515560563e-08 | AA32: 4.648891411840273e-08 | AB32: 0.999999953511086 | AC32: 0.00039860001687751467 | AD32: 0.0017374751722556642 | AE32: 0.9982625248277444 | AF32: 0.0015196213889436898 | AG32: 0.006837918224936904 | AH32: 0.993162081775063 | AI32: 0.0003541924255187631 | AJ32: 0.001587678823803115 | AK32: 0.9984123211761969 | AL32: 0.0020074544282379565 | AM32: 0.008948676374768857 | AN32: 0.9910513236252312 | AO32: 0.005976138572765979 | AP32: 0.026262883360128365 | AQ32: 0.9737371166398716 | AR32: 0.020147597700153713 | AS32: 0.08318854889104675 | AT32: 0.9168114511089532
A33: P33 | B33: 1 | C33: Mixed linear-quadratic drag | D33: F_drag = b*v + c2*v**2 | E33: (-b + sqrt(b**2 + 4*c2*F_drag))/(2*c2) | F33: v | G33: F_drag | H33: b=[0.5, 2]; c2=[0.1, 0.5] | I33: (none) | J33: (-b + sqrt(4*F_drag*c2 + b**2))/(2*c2) | K33: F_drag*p2*(F_drag + p3)**p4 + p0 + p1 + p5*p6**sin(F_drag)*(F_drag + p7)*cos(F_drag*p8*(F_drag + p3) + F_drag*p8) | L33: [0.133290280000000, -0.129755780000000, 1.29826220000000, 2.76258590000000, -0.410314860000000, -4.23657900000000e-5, 0.0145153060000000, -4.60586170000000, 7.70725977627366] | M33: [p0, p1, p2, p3, p4, p5, p6, p7, p8] | N33: 0.0010175985908529 | O33: 0.0010171237025345 | P33: 0.9994651072678103 | Q33: 37 | R33: 0.0009830291 | S33: 0.0009946062650351 | T33: 0 | U33: 65 | V33: =IF(U33>=[1]评分标准!$B$5,[1]评分标准!$A$5,IF(U33>=[1]评分标准!$B$6,[1]评分标准!$A$6,IF(U33>=[1]评分标准!$B$7,[1]评分标准!$A$7,IF(U33>=[1]评分标准!$B$8,[1]评分标准!$A$8,[1]评分标准!$A$9)))) -> 中等相似 | W33: 7.115461395454844e-07 | X33: 3.792427108769847e-07 | Y33: 0.9999996207572892 | Z33: 1.968791980924087e-06 | AA33: 1.0899964896682023e-06 | AB33: 0.9999989100035103 | AC33: 2.6019887062789544e-06 | AD33: 1.464308464796886e-06 | AE33: 0.9999985356915352 | AF33: 1.4209461753371955e-06 | AG33: 7.840039221421003e-07 | AH33: 0.9999992159960778 | AI33: 0.0010750942729307097 | AJ33: 0.0005873254156044603 | AK33: 0.9994126745843955 | AL33: 0.009606127486720482 | AM33: 0.005217469049171905 | AN33: 0.994782530950828 | AO33: 0.026793189088796583 | AP33: 0.014414784097971043 | AQ33: 0.985585215902029 | AR33: 0.10732906705762221 | AS33: 0.055277364797056174 | AT33: 0.9447226352029439
A34: P34 | B34: 1 | C34: Vis-viva orbital speed | D34: v = sqrt(G*M*(2/r - 1/a_orbit)) | E34: 2*G*M*a_orbit/(a_orbit*v**2 + G*M) | F34: r | G34: v | H34: M=[2, 5]; a_orbit=[4, 8] | I34: G=1 | J34: 2*M*a_orbit/(M + a_orbit*v**2) | K34: p0*(p1 + v**p2)**p3 + p4*(p1 + p5*v)**p3*(p3*v + p6)**p3 | L34: [6.14297005953683, 0.564893300000000, 2, -1, 2.77759480000000e-6, -0.987697540000000, 1.03564790000000] | M34: [p0, p1, p2, p3, p4, p5, p6] | N34: 0.0039783888604558 | O34: 0.0028756397588628 | P34: 0.9980127804340668 | Q34: 21 | R34: 0.0016628403 | S34: 4.380866195365966e-05 | T34: 6 | U34: 98 | V34: =IF(U34>=[1]评分标准!$B$5,[1]评分标准!$A$5,IF(U34>=[1]评分标准!$B$6,[1]评分标准!$A$6,IF(U34>=[1]评分标准!$B$7,[1]评分标准!$A$7,IF(U34>=[1]评分标准!$B$8,[1]评分标准!$A$8,[1]评分标准!$A$9)))) -> 高度相似 | W34: 6.053099311825656e-22 | X34: 2.983151370506896e-22 | Y34: 1 | Z34: 1.4943740786083936e-22 | AA34: 7.537223989196404e-23 | AB34: 1 | AC34: 9.13398011844193e-23 | AD34: 4.5433798734619904e-23 | AE34: 1 | AF34: 8.161827741047872e-23 | AG34: 4.054118748883521e-23 | AH34: 1 | AI34: 0.0017070221048059997 | AJ34: 0.0008432310965789461 | AK34: 0.9991567689034211 | AL34: 0.015308091051810975 | AM34: 0.007510617339963608 | AN34: 0.9924893826600364 | AO34: 0.04235896970594112 | AP34: 0.020524867365602287 | AQ34: 0.9794751326343978 | AR34: 0.17184285842725092 | AS34: 0.07799661923806367 | AT34: 0.9220033807619363
A35: P35 | B35: 1 | C35: Schwarzschild gravitational redshift | D35: z = 1/sqrt(1-r_s/r) - 1 | E35: r_s*(1+z)**2/(z*(z+2)) | F35: r | G35: z | H35: r_s=[1, 3] | I35: (none) | J35: r_s*(z + 1)**2/(z*(z + 2)) | K35: p0 + p1*z**p2 + p3*(p4 + p5**z + p6*sin(p7)**p2*sin(p8*z**p2))**p2 | L35: [2.18279170000000, 1.08373560000000, -1, 0.678298900000000, -0.999306440000000, 103.755110000000, -0.00963807951242112, 2.63908500000000, 5.18592400000000] | M35: [p0, p1, p2, p3, p4, p5, p6, p7, p8] | N35: 0.0042984117402286 | O35: 0.0042816389489956 | P35: 0.99895099690044 | Q35: 23 | R35: 0.0040451554 | S35: 0.0006251967987913 | T35: 5 | U35: 60 | V35: =IF(U35>=[1]评分标准!$B$5,[1]评分标准!$A$5,IF(U35>=[1]评分标准!$B$6,[1]评分标准!$A$6,IF(U35>=[1]评分标准!$B$7,[1]评分标准!$A$7,IF(U35>=[1]评分标准!$B$8,[1]评分标准!$A$8,[1]评分标准!$A$9)))) -> 中等相似 | W35: 1.6522949924105513e-07 | X35: 3.8777261588926686e-08 | Y35: 0.9999999612227384 | Z35: 2.1495071298420272e-07 | AA35: 5.2533614978657005e-08 | AB35: 0.999999947466385 | AC35: 2.741143710857091e-06 | AD35: 6.744599915472847e-07 | AE35: 0.9999993255400086 | AF35: 6.890609468552717e-08 | AG35: 1.6483524791133105e-08 | AH35: 0.9999999835164752 | AI35: 0.003989387595233668 | AJ35: 0.00103778732469213 | AK35: 0.9989622126753079 | AL35: 0.0368198929076608 | AM35: 0.009479423726067474 | AN35: 0.9905205762739326 | AO35: 0.10181441484338577 | AP35: 0.025811350371725945 | AQ35: 0.974188649628274 | AR35: 0.40346190464180426 | AS35: 0.09550961722999557 | AT35: 0.9044903827700045
A36: P36 | B36: 1 | C36: Capacitor charging with effective time constant | D36: V = V_inf*(1-exp(-t/tau)) | E36: =-tau*LOG(1-v/v_inf) -> #NAME? | F36: t | G36: V | H36: V_inf=[8, 12]; tau=[1, 4] | I36: (none) | J36: =-tau*LOG(-v/v_inf+1) -> #NAME? | K36: (V + exp(p0*(V + p1)**p2*(p4 + cos(V + p5))*sin(p1**V*p3)**p2 + sin(V*p6)))**p7*atanh(p2 + Mod(V*p9 + p8, p10)) | L36: [0.917046532634986, 0.765040640000000, -1, 1.74724110000000, 0.721354212137271, 0.0622663130000000, 0.640460598767895, 1/2, 1.00000000000000, 0.0956158100000000, 2] | M36: [p0, p1, p2, p3, p4, p5, p6, p7, p8, p9, p10] | N36: 1.0615326713504816 | O36: 0.0014374111139555 | P36: 0.7917111917160853 | Q36: 36 | R36: 0.00077350857 | S36: 0.0036828008224695 | T36: 1 | U36: 50 | V36: =IF(U36>=[1]评分标准!$B$5,[1]评分标准!$A$5,IF(U36>=[1]评分标准!$B$6,[1]评分标准!$A$6,IF(U36>=[1]评分标准!$B$7,[1]评分标准!$A$7,IF(U36>=[1]评分标准!$B$8,[1]评分标准!$A$8,[1]评分标准!$A$9)))) -> 较低相似 | W36: 1.4263741499681062 | X36: 0.27940809677699235 | Y36: 0.7205919032230076 | Z36: 2.5160895319002288 | AA36: 0.49824768921048895 | AB36: 0.5017523107895111 | AC36: 2.6491185131404658 | AD36: 0.5155521849958102 | AE36: 0.48444781500418976 | AF36: 1.287317588377184 | AG36: 0.3686489421913168 | AH36: 0.6313510578086832 | AI36: 1.3129080936206352 | AJ36: 0.37511565737442876 | AK36: 0.6248843426255712 | AL36: 1.1025720250827171 | AM36: 0.3223185434744736 | AN36: 0.6776814565255265 | AO36: 1.3302761919695993 | AP36: 0.3790874092932529 | AQ36: 0.6209125907067471 | AR36: 1.2215039218632089 | AS36: 0.33731177995099554 | AT36: 0.6626882200490045
A37: P37 | B37: 1 | C37: Driven-oscillator response with effective drive acceleration | D37: Amp = a0/sqrt((omega0**2-omega**2)**2 + 4*gamma**2*omega**2) | E37: sqrt(omega0**2 - 2*gamma**2 + sqrt((a0/Amp)**2 + 4*gamma**2*(gamma**2-omega0**2))) | F37: omega | G37: Amp | H37: a0=[1, 3]; omega0=[3, 5]; gamma=[0.2, 0.6] | I37: (none) | J37: sqrt(-2*gamma**2 + omega0**2 + sqrt(4*gamma**2*(gamma**2 - omega0**2) + a0**2/Amp**2)) | K37: Amp*(Amp*p7 + p4 + p5*sin(p6*atan(Amp)**p2) + p8*sin(p9*atan(Amp)**p2)) + (p0 + p1*tanh(Amp)**p2)**p3 | L37: [18.8127630000000, 2.15821770000000, -1, 1/2, -0.0221352066374147, 0.0270607416808950, 23.2190800000000, -0.607367000000000, -0.0296417234527150, 19.9120400000000] | M37: [p0, p1, p2, p3, p4, p5, p6, p7, p8, p9] | N37: 0.0040333048279865 | O37: 0.0040323518673697 | P37: 0.9911927225301604 | Q37: 32 | R37: 0.0039740955 | S37: 1.2820362974451644e-05 | T37: 7 | U37: 45 | V37: =IF(U37>=[1]评分标准!$B$5,[1]评分标准!$A$5,IF(U37>=[1]评分标准!$B$6,[1]评分标准!$A$6,IF(U37>=[1]评分标准!$B$7,[1]评分标准!$A$7,IF(U37>=[1]评分标准!$B$8,[1]评分标准!$A$8,[1]评分标准!$A$9)))) -> 较低相似 | W37: 1.409996102756279e-14 | X37: 3.2262866495096924e-14 | Y37: 0.9999999999999678 | Z37: 9.698727047968312e-12 | AA37: 2.2338574239928475e-11 | AB37: 0.9999999999776614 | AC37: 5.439339074740417e-10 | AD37: 1.2471680111658455e-09 | AE37: 0.9999999987528321 | AF37: 1.003914128670888e-14 | AG37: 2.2819779597809595e-14 | AH37: 0.9999999999999771 | AI37: 0.004110369761341678 | AJ37: 0.008883098925086364 | AK37: 0.9911169010749137 | AL37: 0.03589237401268637 | AM37: 0.07269686484268106 | AN37: 0.9273031351573189 | AO37: 0.10284874643041034 | AP37: 0.18339713671752417 | AQ37: 0.8166028632824759 | AR37: 0.414048133209033 | AS37: 0.47736119058882936 | AT37: 0.5226388094111706
A38: P39 | B38: 1 | C38: Gaussian-beam radius | D38: w = w0*sqrt(1+(z/z_R)**2) | E38: z_R*sqrt((w/w0)**2 - 1) | F38: z | G38: w | H38: w0=[1, 2]; z_R=[2, 5] | I38: (none) | J38: z_R*sqrt(w**2/w0**2 - 1) | K38: p0 + p1*(p2**cos(w)*w)**p3 + p4*w + log(p5 + (p6 + p7*w)**p8) | L38: [0.106403865000000, -1, 0.960596430352107, -0.108771680000000, 2.13450170000000, 0.100789640000000, -1.34131420000000, 1.02735750000000, 0.608648500000000] | M38: [p0, p1, p2, p3, p4, p5, p6, p7, p8] | N38: 0.0012723472574145 | O38: 0.0012376411626808 | P38: 0.9991340681216864 | Q38: 33 | R38: 0.0011435318 | S38: 3.75781156605254e-05 | T38: 2 | U38: 50 | V38: =IF(U38>=[1]评分标准!$B$5,[1]评分标准!$A$5,IF(U38>=[1]评分标准!$B$6,[1]评分标准!$A$6,IF(U38>=[1]评分标准!$B$7,[1]评分标准!$A$7,IF(U38>=[1]评分标准!$B$8,[1]评分标准!$A$8,[1]评分标准!$A$9)))) -> 较低相似 | W38: 8.482660683549616e-05 | X38: 5.6621974583673114e-05 | Y38: 0.9999433780254163 | Z38: 6.121473945901679e-06 | AA38: 4.147070143653781e-06 | AB38: 0.9999958529298564 | AC38: 0.0001312252675279353 | AD38: 8.776752138652308e-05 | AE38: 0.9999122324786134 | AF38: 2.931535868443905e-05 | AG38: 1.9554981890545175e-05 | AH38: 0.9999804450181095 | AI38: 0.0011813003682101192 | AJ38: 0.0007902940225751861 | AK38: 0.9992097059774248 | AL38: 0.010293958792850324 | AM38: 0.0068469892708406255 | AN38: 0.9931530107291593 | AO38: 0.027769164075446717 | AP38: 0.018244882477790155 | AQ38: 0.9817551175222099 | AR38: 0.11326247561695975 | AS38: 0.07040196891136852 | AT38: 0.9295980310886315
A39: P40 | B39: 1 | C39: Net Stefan-Boltzmann radiation | D39: P = Area*sigma*(T**4-Ta**4) | E39: (P/(Area*sigma) + Ta**4)**(1/4) | F39: T | G39: P | H39: Area=[1, 3]; Ta=[1, 2.5] | I39: sigma=1 | J39: (Ta**4 + P/Area)**(1/4) | K39: (P*p1 + P**p2*(cos(P*p3) + cos(P*p5 + p4) + cos(P*p7 + p6) + cos(P*p9 + p8)) + p0)**p10 | L39: [3.83890720000000, 0.715036758252150, 0.124282330000000, 34.8175631069202, 1.00044610000000, 0.971859327249818, 0.632799863720602, 1.94240874612271, -1.39989340000000, 0.832865540521407, 0.249764340000000] | M39: [p0, p1, p2, p3, p4, p5, p6, p7, p8, p9, p10] | N39: 0.0044055090322753 | O39: 0.0044006504698127 | P39: 0.996829946033732 | Q39: 37 | R39: 0.0043292055 | S39: 0.0003298362514087 | T39: 0 | U39: 95 | V39: =IF(U39>=[1]评分标准!$B$5,[1]评分标准!$A$5,IF(U39>=[1]评分标准!$B$6,[1]评分标准!$A$6,IF(U39>=[1]评分标准!$B$7,[1]评分标准!$A$7,IF(U39>=[1]评分标准!$B$8,[1]评分标准!$A$8,[1]评分标准!$A$9)))) -> 高度相似 | W39: 1.1180417568437153e-20 | X39: 7.857972524603175e-21 | Y39: 1 | Z39: 9.798055121775853e-22 | AA39: 6.88767415870253e-22 | AB39: 1 | AC39: 6.644480787033479e-20 | AD39: 4.7243384146569406e-20 | AE39: 1 | AF39: 4.924478708575821e-21 | AG39: 3.463543349949228e-21 | AH39: 1 | AI39: 0.004319065231047264 | AJ39: 0.0030380775870988298 | AK39: 0.9969619224129012 | AL39: 0.038790946089540056 | AM39: 0.02663300075034604 | AN39: 0.9733669992496539 | AO39: 0.10877899352129394 | AP39: 0.07143969234882949 | AQ39: 0.9285603076511705 | AR39: 0.4296881255506032 | AS39: 0.23329002666121784 | AT39: 0.7667099733387821
A40: P41 | B40: 1 | C40: Polytropic/adiabatic pressure-volume law | D40: P = K_poly*V**(-gamma) | E40: (K_poly/P)**(1/gamma) | F40: V | G40: P | H40: K_poly=[10, 30]; gamma=[1.2, 1.7] | I40: (none) | J40: (K_poly/P)**(1/gamma) | K40: (P**p1*p0 + p2*p3**P*sin(P*p2 + P**p5*p4))**p6 | L40: [10.0773000000000, -0.725155300000000, -1, 0.260727880000000, 1.48713648000000, 3, 0.999771800000000] | M40: [p0, p1, p2, p3, p4, p5, p6] | N40: 0.0004153080187532 | O40: 0.000414898662097 | P40: 0.9994671571190008 | Q40: 29 | R40: 0.00040341282 | S40: 3.392696164301802e-05 | T40: 5 | U40: 98 | V40: =IF(U40>=[1]评分标准!$B$5,[1]评分标准!$A$5,IF(U40>=[1]评分标准!$B$6,[1]评分标准!$A$6,IF(U40>=[1]评分标准!$B$7,[1]评分标准!$A$7,IF(U40>=[1]评分标准!$B$8,[1]评分标准!$A$8,[1]评分标准!$A$9)))) -> 高度相似 | W40: 1.171200198832054e-23 | X40: 1.5195433419846184e-23 | Y40: 1 | Z40: 1.1616168898026621e-23 | AA40: 1.721459248341321e-23 | AB40: 1 | AC40: 2.0810705128648917e-19 | AD40: 3.488751360715886e-19 | AE40: 1 | AF40: 1.1903060961772212e-23 | AG40: 1.538498666543242e-23 | AH40: 1 | AI40: 0.00040926768727313965 | AJ40: 0.0005301780452098279 | AK40: 0.9994698219547902 | AL40: 0.0037332347987701214 | AM40: 0.00480245909920183 | AN40: 0.9951975409007981 | AO40: 0.010304640312352984 | AP40: 0.013163748692667124 | AQ40: 0.9868362513073329 | AR40: 0.04160303408211695 | AS40: 0.051005074787289995 | AT40: 0.94899492521271
...
